Workbook
Name Slicer_Discount_Category: #N/A
Name Slicer_Discount_Range: #N/A
Name Slicer_Rating_Category: #N/A

Sheet Original Dataset
A1: Product | B1: Current price | C1: old price | D1: Discount | E1: Review | F1: Ratingd
A2: 115 Piece Set Of Multifunctional Precision Screwdrivers | B2: KSh 950 | C2: KSh 1,525 | D2: 0.38 | E2: -2 | F2: 4.5 out of 5
A3: Metal Decorative Hooks Key Hangers Entryway Wall Hooks Towel Hooks - Home | B3: KSh 527 | C3: KSh 999 | D3: 0.47 | E3: -14 | F3: 4.1 out of 5
A4: Portable Mini Cordless Car Vacuum Cleaner - Blue | B4: KSh 2,199 | C4: KSh 2,923 | D4: 0.25 | E4: -24 | F4: 4.6 out of 5
A5: Weighing Scale Digital Bathroom Body Fat Scale USB-Black | B5: KSh 1,580 | C5: KSh 2,499 | D5: 0.37 | E5: -7 | F5: 4.7 out of 5
A6: Portable Home Small Air Humidifier 3-Speed Fan - Green | B6: KSh 1,740 | C6: KSh 2,356 | D6: 0.26 | E6: -5 | F6: 4.8 out of 5
A7: 220V 60W Electric Soldering Iron Kits With Tools, Tips, And Multimeter | B7: KSh 2,999 | C7: KSh 3,290 | D7: 0.09 | E7: -15 | F7: 4 out of 5
A8: 137 Pieces Cake Decorating Tool Set Baking Supplies | B8: KSh 2,319 | C8: KSh 3,032 | D8: 0.24 | E8: -55 | F8: 4.6 out of 5
A9: Desk Foldable Fan Adjustable Fan Strong Wind 3 Gear Usb | B9: KSh 988 | C9: KSh 1,580 | D9: 0.37 | E9: -2 | F9: 4 out of 5
A10: LASA FOLDING TABLE SERVING STAND | B10: KSh 1,274 | C10: KSh 2,800 | D10: 0.55 | E10: -5 | F10: 4.8 out of 5
A11: 13 In 1 Home Repair Tools Box Kit Set | B11: KSh 1,600 | C11: KSh 2,929 | D11: 0.45 | E11: -5 | F11: 3.8 out of 5
A12: Genebre 115 In 1 Screwdriver Repairing Tool Set For IPhone Cellphone Hand Tool | B12: KSh 799 | C12: KSh 999 | D12: 0.2 | E12: -12 | F12: 4.1 out of 5
A13: 100 Pcs Crochet Hook Tool Set Knitting Hook Set With Box | B13: KSh 990 | C13: KSh 1,500 | D13: 0.34 | E13: -39 | F13: 4.7 out of 5
... A22: 3PCS Single Head Knitting Crochet Sweater Needle Set | B22: KSh 38 | C22: KSh 80 | D22: 0.53 | E22: -13 | F22: 3.3 out of 5
A23: 4pcs Bathroom/Kitchen Towel Rack,Roll Paper Holder,Towel Bars,Hook | B23: KSh 1,860 | C23: KSh 3,220 | D23: 0.42
A24: LED Romantic Spaceship Starry Sky Projector,Children's Bedroom Night Light-Blue | B24: KSh 880 | C24: KSh 1,350 | D24: 0.35 | E24: -6 | F24: 4 out of 5
A25: Foldable Overbed Table/Desk | B25: KSh 1,650 | C25: KSh 2,150 | D25: 0.23 | E25: -14 | F25: 4.4 out of 5
A26: LASA 3 Tier Bamboo Shoe Bench Storage Shelf | B26: KSh 2,048 | C26: KSh 4,500 | D26: 0.54 | E26: -7 | F26: 4.3 out of 5
A27: Electronic Digital Display Vernier Caliper | B27: KSh 420 | C27: KSh 647 | D27: 0.35 | E27: -49 | F27: 4.6 out of 5
A28: Portable Wardrobe Nonwoven With 3 Hanging Rods And 6 Storage Shelves | B28: KSh 2,880 | C28: KSh 3,520 | D28: 0.18 | E28: -12 | F28: 3.8 out of 5
A29: 12 Litre Black Insulated Lunch Box | B29: KSh 1,350 | C29: KSh 1,990 | D29: 0.32 | E29: -13 | F29: 3.8 out of 5
A30: 52 Pieces Cake Decorating Tool Set Gift Kit Baking Supplies | B30: KSh 1,758 | C30: KSh 2,499 | D30: 0.3 | E30: -20 | F30: 4.1 out of 5
A31: MultiFunctional Storage Rack Multi-layer Bookshelf | B31: KSh 2,200 | C31: KSh 4,080 | D31: 0.46
A32: Exfoliate And Exfoliate Face Towel - Black | B32: KSh 185 | C32: KSh 382 | D32: 0.52 | E32: -9 | F32: 4.3 out of 5
A33: 12 Litre Insulated Lunch Box Grey | B33: KSh 980 | C33: KSh 1,490 | D33: 0.34 | E33: -12 | F33: 4.7 out of 5
A34: LED Eye Protection Desk Lamp , Study, Reading, USB Fan - Double Pen Holder | B34: KSh 1,820 | C34: KSh 3,490 | D34: 0.48 | E34: -9 | F34: 4.3 out of 5
A35: 53Pcs/Set Yarn Knitting Crochet Hooks With Bag - Fortune Cat | B35: KSh 1,940 | C35: KSh 2,650 | D35: 0.27 | E35: -20 | F35: 4.7 out of 5
A36: 53 Pieces/Set Yarn Knitting Crochet Hooks With Bag - Pansies | B36: KSh 1,980 | C36: KSh 2,699 | D36: 0.27 | E36: -32 | F36: 4.5 out of 5
A37: DIY File Folder, Office Drawer File Holder, Pen Holder, Desktop Storage Rack | B37: KSh 1,620 | C37: KSh 2,690 | D37: 0.4 | E37: -1 | F37: 5 out of 5
A38: Classic Black Cat Cotton Hemp Pillow Case For Home Car | B38: KSh 171 | C38: KSh 360 | D38: 0.53 | E38: -2 | F38: 5 out of 5
A39: Punch-free Great Load Bearing Bathroom Storage Rack Wall Shelf-White | B39: KSh 389 | C39: KSh 656 | D39: 0.41 | E39: -36 | F39: 4.3 out of 5
A40: 1/2/3 Seater Elastic Sofa Cover,Living Room/Home Decor Chair Cover-Grey | B40: KSh 1,620 - KSh 1,980 | C40: KSh 2,200 - KSh 3,200 | D40: 0.38 | E40: -2 | F40: 4.5 out of 5
A41: LASA Stainless Steel Double Wall Mount Soap Dispenser - 500ml | B41: KSh 2,750 | C41: KSh 4,471 | D41: 0.38
A42: 4M Float Switch Water Level Controller -Water Tank | B42: KSh 475 | C42: KSh 931 | D42: 0.49
A43: Modern Sofa Throw Pillow Cover-45x45cm-Blue&Red | B43: KSh 238 | C43: KSh 476 | D43: 0.5
A44: Balloon Insert, Birthday Party Balloon Set, PU Leather | B44: KSh 610 | C44: KSh 1,060 | D44: 0.42
A45: Balloon Insert, Birthday Party Balloon Set, PU Leather | B45: KSh 610 | C45: KSh 1,060 | D45: 0.42
A46: Shower Cap Wide Elastic Band Cover Reusable Bashroom Cap | B46: KSh 2,132 | C46: KSh 2,169 | D46: 0.02
A47: Christmas Elk Fence Yard Lawn Decorations Cute For Holidays | B47: KSh 999 | C47: KSh 2,000 | D47: 0.5
A48: 60W Hot Melt Glue Sprayer - Efficient And Stable Glue Dispensing | B48: KSh 1,190 | C48: KSh 1,785 | D48: 0.33
...

Sheet Project Writeup
B2: Introduction and Overview
B3: This report documents every step taken to analyse the Jumia e-commerce dataset, clean the data, enrich it with calculated columns, perform descriptive and trend analysis, and finally present the findings in an interactive Excel dashboard complete with pivot tables, charts, and slicers.
B4: The dataset contained product listings scraped from Jumia, including pricing, discount information, customer reviews, and star ratings. The goal was to transform raw, unclean data into actionable business insights that a decision-maker can explore interactively.
B6: Original Dataset Overview
B7: Total rows (raw): 117, Columns: 9
B8: Columns: Product, Current price, old price, Absolute discount, Discount, Disc %, Review, Ratings, Ratings 2
B9: Issues found: summary rows appended at the bottom, one product with a price range instead of a single value, missing values in Review/Ratings columns, mixed text and numeric formats in price fields.
B11: STEP 1 Data Cleaning & Preparation
B12: 1.1 Identifying Problems in the Raw Data
B13: Before any analysis could begin, the raw data was carefully inspected for quality issues. The following problems were found and resolved:
B15: Problem Found | C15: Location / Details | D15: Action Taken
B16: Summary rows appended to data | C16: Rows 113–117: labelled "average", "max", "min" — not product rows | D16: Deleted all 5 rows; only rows 1–112 retained
B17: Blank / duplicate rows | C17: Rows 112 and 115 were completely empty (NaN in every column) | D17: Removed as part of the summary-row cleanup
B18: Price range instead of single value | C18: Sofa Cover product had "1,620 – 1,980" in Current Price — not numeric | D18: Row removed; cannot average a range in calculations
B19: Price columns stored as text | C19: KSh prefix and commas (e.g. "KSh 2,199") prevented arithmetic | D19: Stripped all text; converted to plain integers
B20: Missing Discount % for some rows | C20: 4 rows had Discount and Disc % as blank despite having prices | D20: Recalculated: Discount % = (Old Price - Current Price) / Old Price
B21: Missing Reviews & Ratings | C21: 60 products had no review count; 59 had no star rating | D21: Left blank (legitimate — product has 0 reviews); tagged as N/A in category column
B23: After cleaning, the working dataset contained 111 products with complete, numeric pricing data.
B25: 1.2 Data Enrichment — Calculated Columns
B26: Four new columns were added to the Cleaned Data sheet. Each one uses an Excel formula that references other cells in the same row, so the values update automatically if the source data changes.
B28: New Column | C28: Column Letter | D28: Excel Formula Used
B29: Absolute Discount (KES) | C29: Column D | D29: C2-B2 (Old Price minus Current Price)
B30: Discount % | C30: Column E | D30: IF(C2>0,(C2-B2)/C2,0) formatted as 0.0%
B31: Discount Label | C31: Column F | D31: IF(E2="","N/A",IF(E2<0.2,"Low Discount",IF(E2<=0.4,"Medium Discount","High Discount")))
B32: Rating Category | C32: Column J | D32: IF(H2="","N/A",IF(H2<3,"Poor",IF(H2<4.5,"Average","Excellent")))
B33: Discount Category | C33: Column K | D33: F2 (mirrors Discount Label — for slicer compatibility)
B35: 1.3 Conditional Formatting Applied
B36: Two colour-scale rules were applied directly on the Cleaned Data sheet to make patterns immediately visible:
B37: • Discount % column (E): Green = low discount (cheaper product), transitioning through yellow to Red = high discount. This quickly shows which products are most heavily marked down.
B38: • Rating column (H): Red = low rating (poor product), transitioning through yellow to Green = high rating. Allows instant quality scanning down the column.
B40: STEP 2 Data Analysis — Descriptive Statistics & Trend Analysis
B41: 2.1 Descriptive Statistics
B42: All descriptive statistics were calculated on the Analysis sheet using cell-reference formulas that pull directly from the Cleaned Data sheet. This ensures that if any value is corrected in Cleaned Data, the statistics update automatically.
B44: Statistic | C44: Function | D44: Formula / Result Description
B45: Total Products | C45: COUNTA | D45: =COUNTA('Cleaned Data'!A2:A112) → 111 products
B46: Average Current Price | C46: AVERAGE | D46: AVERAGE('Cleaned Data'!B2:B112)
B47: Average Old Price | C47: AVERAGE | D47: AVERAGE('Cleaned Data'!C2:C112)
B48: Average Discount % | C48: AVERAGE | D48: AVERAGE('Cleaned Data'!E2:E112) → shown as 0.0%
B49: Average Rating (reviewed only) | C49: AVERAGEIF | D49: =AVERAGEIF(H2:H112,"<>",H2:H112) excludes blanks
B50: Total Reviews | C50: SUM | D50: SUM('Cleaned Data'!G2:G112)
...

Sheet PivotSource
A1: Product | B1: Current Price (KES) | C1: Old Price (KES) | D1: Absolute Discount (KES) | E1: Discount % | F1: Discount Label | G1: Reviews | H1: Rating (out of 5) | I1: Rating Label | J1: Rating Category | K1: Discount Category
A2: 115 Piece Set Of Multifunctional Precision Screwdrivers | B2: 950 | C2: 1525 | D2: 575 | E2: 0.37704918 | F2: Medium Discount | G2: 2 | H2: 4.5 | I2: excellent | J2: Excellent | K2: Medium Discount
A3: Metal Decorative Hooks Key Hangers Entryway Wall Hooks Towel Hooks - Home | B3: 527 | C3: 999 | D3: 472 | E3: 0.47247247 | F3: High Discount | G3: 14 | H3: 4.1 | I3: Average | J3: Average | K3: High Discount
A4: Portable Mini Cordless Car Vacuum Cleaner - Blue | B4: 2199 | C4: 2923 | D4: 724 | E4: 0.24769073 | F4: Medium Discount | G4: 24 | H4: 4.6 | I4: excellent | J4: Excellent | K4: Medium Discount
A5: Weighing Scale Digital Bathroom Body Fat Scale USB-Black | B5: 1580 | C5: 2499 | D5: 919 | E5: 0.3677471 | F5: Medium Discount | G5: 7 | H5: 4.7 | I5: excellent | J5: Excellent | K5: Medium Discount
A6: Portable Home Small Air Humidifier 3-Speed Fan - Green | B6: 1740 | C6: 2356 | D6: 616 | E6: 0.2614601 | F6: Medium Discount | G6: 5 | H6: 4.8 | I6: excellent | J6: Excellent | K6: Medium Discount
A7: 220V 60W Electric Soldering Iron Kits With Tools, Tips, And Multimeter | B7: 2999 | C7: 3290 | D7: 291 | E7: 0.088449848 | F7: Low Discount | G7: 15 | H7: 4 | I7: Average | J7: Average | K7: Low Discount
A8: 137 Pieces Cake Decorating Tool Set Baking Supplies | B8: 2319 | C8: 3032 | D8: 713 | E8: 0.23515831 | F8: Medium Discount | G8: 55 | H8: 4.6 | I8: excellent | J8: Excellent | K8: Medium Discount
A9: Desk Foldable Fan Adjustable Fan Strong Wind 3 Gear Usb | B9: 988 | C9: 1580 | D9: 592 | E9: 0.37468354 | F9: Medium Discount | G9: 2 | H9: 4 | I9: Average | J9: Average | K9: Medium Discount
A10: LASA FOLDING TABLE SERVING STAND | B10: 1274 | C10: 2800 | D10: 1526 | E10: 0.545 | F10: High Discount | G10: 5 | H10: 4.8 | I10: excellent | J10: Excellent | K10: High Discount
A11: 13 In 1 Home Repair Tools Box Kit Set | B11: 1600 | C11: 2929 | D11: 1329 | E11: 0.45373848 | F11: High Discount | G11: 5 | H11: 3.8 | I11: Average | J11: Average | K11: High Discount
A12: Genebre 115 In 1 Screwdriver Repairing Tool Set For IPhone Cellphone Hand Tool | B12: 799 | C12: 999 | D12: 200 | E12: 0.2002002 | F12: Medium Discount | G12: 12 | H12: 4.1 | I12: Average | J12: Average | K12: Medium Discount
A13: 100 Pcs Crochet Hook Tool Set Knitting Hook Set With Box | B13: 990 | C13: 1500 | D13: 510 | E13: 0.34 | F13: Medium Discount | G13: 39 | H13: 4.7 | I13: excellent | J13: Excellent | K13: Medium Discount
... A22: 3PCS Single Head Knitting Crochet Sweater Needle Set | B22: 38 | C22: 80 | D22: 42 | E22: 0.525 | F22: High Discount | G22: 13 | H22: 3.3 | I22: Average | J22: Average | K22: High Discount
A23: 4pcs Bathroom/Kitchen Towel Rack,Roll Paper Holder,Towel Bars,Hook | B23: 1860 | C23: 3220 | D23: 1360 | E23: 0.42236025 | F23: High Discount | J23: N/A | K23: High Discount
A24: LED Romantic Spaceship Starry Sky Projector,Children's Bedroom Night Light-Blue | B24: 880 | C24: 1350 | D24: 470 | E24: 0.34814815 | F24: Medium Discount | G24: 6 | H24: 4 | I24: Average | J24: Average | K24: Medium Discount
A25: Foldable Overbed Table/Desk | B25: 1650 | C25: 2150 | D25: 500 | E25: 0.23255814 | F25: Medium Discount | G25: 14 | H25: 4.4 | I25: Average | J25: Average | K25: Medium Discount
A26: LASA 3 Tier Bamboo Shoe Bench Storage Shelf | B26: 2048 | C26: 4500 | D26: 2452 | E26: 0.54488889 | F26: High Discount | G26: 7 | H26: 4.3 | I26: Average | J26: Average | K26: High Discount
A27: Electronic Digital Display Vernier Caliper | B27: 420 | C27: 647 | D27: 227 | E27: 0.35085008 | F27: Medium Discount | G27: 49 | H27: 4.6 | I27: excellent | J27: Excellent | K27: Medium Discount
A28: Portable Wardrobe Nonwoven With 3 Hanging Rods And 6 Storage Shelves | B28: 2880 | C28: 3520 | D28: 640 | E28: 0.18181818 | F28: Low Discount | G28: 12 | H28: 3.8 | I28: Average | J28: Average | K28: Low Discount
A29: 12 Litre Black Insulated Lunch Box | B29: 1350 | C29: 1990 | D29: 640 | E29: 0.32160804 | F29: Medium Discount | G29: 13 | H29: 3.8 | I29: Average | J29: Average | K29: Medium Discount
A30: 52 Pieces Cake Decorating Tool Set Gift Kit Baking Supplies | B30: 1758 | C30: 2499 | D30: 741 | E30: 0.29651861 | F30: Medium Discount | G30: 20 | H30: 4.1 | I30: Average | J30: Average | K30: Medium Discount
A31: MultiFunctional Storage Rack Multi-layer Bookshelf | B31: 2200 | C31: 4080 | D31: 1880 | E31: 0.46078431 | F31: High Discount | J31: N/A | K31: High Discount
A32: Exfoliate And Exfoliate Face Towel - Black | B32: 185 | C32: 382 | D32: 197 | E32: 0.51570681 | F32: High Discount | G32: 9 | H32: 4.3 | I32: Average | J32: Average | K32: High Discount
A33: 12 Litre Insulated Lunch Box Grey | B33: 980 | C33: 1490 | D33: 510 | E33: 0.34228188 | F33: Medium Discount | G33: 12 | H33: 4.7 | I33: excellent | J33: Excellent | K33: Medium Discount
A34: LED Eye Protection Desk Lamp , Study, Reading, USB Fan - Double Pen Holder | B34: 1820 | C34: 3490 | D34: 1670 | E34: 0.47851003 | F34: High Discount | G34: 9 | H34: 4.3 | I34: Average | J34: Average | K34: High Discount
A35: 53Pcs/Set Yarn Knitting Crochet Hooks With Bag - Fortune Cat | B35: 1940 | C35: 2650 | D35: 710 | E35: 0.26792453 | F35: Medium Discount | G35: 20 | H35: 4.7 | I35: excellent | J35: Excellent | K35: Medium Discount
A36: 53 Pieces/Set Yarn Knitting Crochet Hooks With Bag - Pansies | B36: 1980 | C36: 2699 | D36: 719 | E36: 0.26639496 | F36: Medium Discount | G36: 32 | H36: 4.5 | I36: excellent | J36: Excellent | K36: Medium Discount
A37: DIY File Folder, Office Drawer File Holder, Pen Holder, Desktop Storage Rack | B37: 1620 | C37: 2690 | D37: 1070 | E37: 0.39776952 | F37: Medium Discount | G37: 1 | H37: 5 | I37: excellent | J37: Excellent | K37: Medium Discount
A38: Classic Black Cat Cotton Hemp Pillow Case For Home Car | B38: 171 | C38: 360 | D38: 189 | E38: 0.525 | F38: High Discount | G38: 2 | H38: 5 | I38: excellent | J38: Excellent | K38: High Discount
A39: Punch-free Great Load Bearing Bathroom Storage Rack Wall Shelf-White | B39: 389 | C39: 656 | D39: 267 | E39: 0.4070122 | F39: High Discount | G39: 36 | H39: 4.3 | I39: Average | J39: Average | K39: High Discount
A40: LASA Stainless Steel Double Wall Mount Soap Dispenser - 500ml | B40: 2750 | C40: 4471 | D40: 1721 | E40: 0.38492507 | F40: Medium Discount | J40: N/A | K40: Medium Discount
A41: 4M Float Switch Water Level Controller -Water Tank | B41: 475 | C41: 931 | D41: 456 | E41: 0.48979592 | F41: High Discount | J41: N/A | K41: High Discount
A42: Modern Sofa Throw Pillow Cover-45x45cm-Blue&Red | B42: 238 | C42: 476 | D42: 238 | E42: 0.5 | F42: High Discount | J42: N/A | K42: High Discount
A43: Balloon Insert, Birthday Party Balloon Set, PU Leather | B43: 610 | C43: 1060 | D43: 450 | E43: 0.4245283 | F43: High Discount | J43: N/A | K43: High Discount
A44: Shower Cap Wide Elastic Band Cover Reusable Bashroom Cap | B44: 2132 | C44: 2169 | D44: 37 | E44: 0.017058552 | F44: Low Discount | J44: N/A | K44: Low Discount
A45: Christmas Elk Fence Yard Lawn Decorations Cute For Holidays | B45: 999 | C45: 2000 | D45: 1001 | E45: 0.5005 | F45: High Discount | J45: N/A | K45: High Discount
A46: 60W Hot Melt Glue Sprayer - Efficient And Stable Glue Dispensing | B46: 1190 | C46: 1785 | D46: 595 | E46: 0.33333333 | F46: Medium Discount | J46: N/A | K46: Medium Discount
A47: Car Phone Charging Stand | B47: 671 | C47: 1316 | D47: 645 | E47: 0.49012158 | F47: High Discount | J47: N/A | K47: High Discount
A48: 2pcs Solar Street Light Flood Light Outdoor | B48: 1200 | C48: 1950 | D48: 750 | E48: 0.38461538 | F48: Medium Discount | J48: N/A | K48: Medium Discount
...

Sheet Cleaned Data
A1: Product | B1: Current Price (KES) | C1: Old Price (KES) | D1: Absolute Discount (KES) | E1: Discount % | F1: Discount Label | G1: Reviews | H1: Rating (out of 5) | I1: Rating Label | J1: Rating Category | K1: Discount Category
A2: Anti-Skid Absorbent Insulation Coaster For Home Office | B2: 332 | C2: 684 | D2: =C2-B2 -> 352 | E2: =IF(C2>0,(C2-B2)/C2,0) -> 0.51461988 | F2: =IF(E2="","N/A",IF(E2<0.2,"Low Discount",IF(E2<=0.4,"Medium Discount","High Discount"))) -> High Discount | G2: 2 | H2: 5 | I2: excellent | J2: =IF(H2="","N/A",IF(H2<3,"Poor",IF(H2<4.5,"Average","Excellent"))) -> Excellent | K2: =F2 -> High Discount
A3: Peacock Throw Pillow Cushion Case For Home Car | B3: 195 | C3: 360 | D3: =C3-B3 -> 165 | E3: =IF(C3>0,(C3-B3)/C3,0) -> 0.45833333 | F3: =IF(E3="","N/A",IF(E3<0.2,"Low Discount",IF(E3<=0.4,"Medium Discount","High Discount"))) -> High Discount | G3: 2 | H3: 5 | I3: excellent | J3: =IF(H3="","N/A",IF(H3<3,"Poor",IF(H3<4.5,"Average","Excellent"))) -> Excellent | K3: =F3 -> High Discount
A4: LASA Aluminum Folding Truck Hand Cart - 68kg Max | B4: 2025 | C4: 3971 | D4: =C4-B4 -> 1946 | E4: =IF(C4>0,(C4-B4)/C4,0) -> 0.49005288 | F4: =IF(E4="","N/A",IF(E4<0.2,"Low Discount",IF(E4<=0.4,"Medium Discount","High Discount"))) -> High Discount | G4: 3 | H4: 5 | I4: excellent | J4: =IF(H4="","N/A",IF(H4<3,"Poor",IF(H4<4.5,"Average","Excellent"))) -> Excellent | K4: =F4 -> High Discount
A5: DIY File Folder, Office Drawer File Holder, Pen Holder, Desktop Storage Rack | B5: 1620 | C5: 2690 | D5: =C5-B5 -> 1070 | E5: =IF(C5>0,(C5-B5)/C5,0) -> 0.39776952 | F5: =IF(E5="","N/A",IF(E5<0.2,"Low Discount",IF(E5<=0.4,"Medium Discount","High Discount"))) -> Medium Discount | G5: 1 | H5: 5 | I5: excellent | J5: =IF(H5="","N/A",IF(H5<3,"Poor",IF(H5<4.5,"Average","Excellent"))) -> Excellent | K5: =F5 -> Medium Discount
A6: Classic Black Cat Cotton Hemp Pillow Case For Home Car | B6: 171 | C6: 360 | D6: =C6-B6 -> 189 | E6: =IF(C6>0,(C6-B6)/C6,0) -> 0.525 | F6: =IF(E6="","N/A",IF(E6<0.2,"Low Discount",IF(E6<=0.4,"Medium Discount","High Discount"))) -> High Discount | G6: 2 | H6: 5 | I6: excellent | J6: =IF(H6="","N/A",IF(H6<3,"Poor",IF(H6<4.5,"Average","Excellent"))) -> Excellent | K6: =F6 -> High Discount
A7: Bedroom Simple Floor Hanging Clothes Rack Single Pole Hat Rack - White | B7: 979 | C7: 1920 | D7: =C7-B7 -> 941 | E7: =IF(C7>0,(C7-B7)/C7,0) -> 0.49010417 | F7: =IF(E7="","N/A",IF(E7<0.2,"Low Discount",IF(E7<=0.4,"Medium Discount","High Discount"))) -> High Discount | G7: 1 | H7: 5 | I7: excellent | J7: =IF(H7="","N/A",IF(H7<3,"Poor",IF(H7<4.5,"Average","Excellent"))) -> Excellent | K7: =F7 -> High Discount
A8: Konka Healty Electric Kettle, 24-hour Heat Preservation,1.5L,800W, White | B8: 3640 | C8: 4588 | D8: =C8-B8 -> 948 | E8: =IF(C8>0,(C8-B8)/C8,0) -> 0.20662598 | F8: =IF(E8="","N/A",IF(E8<0.2,"Low Discount",IF(E8<=0.4,"Medium Discount","High Discount"))) -> Medium Discount | G8: 1 | H8: 5 | I8: excellent | J8: =IF(H8="","N/A",IF(H8<3,"Poor",IF(H8<4.5,"Average","Excellent"))) -> Excellent | K8: =F8 -> Medium Discount
A9: Portable Home Small Air Humidifier 3-Speed Fan - Green | B9: 1740 | C9: 2356 | D9: =C9-B9 -> 616 | E9: =IF(C9>0,(C9-B9)/C9,0) -> 0.2614601 | F9: =IF(E9="","N/A",IF(E9<0.2,"Low Discount",IF(E9<=0.4,"Medium Discount","High Discount"))) -> Medium Discount | G9: 5 | H9: 4.8 | I9: excellent | J9: =IF(H9="","N/A",IF(H9<3,"Poor",IF(H9<4.5,"Average","Excellent"))) -> Excellent | K9: =F9 -> Medium Discount
A10: LASA FOLDING TABLE SERVING STAND | B10: 1274 | C10: 2800 | D10: =C10-B10 -> 1526 | E10: =IF(C10>0,(C10-B10)/C10,0) -> 0.545 | F10: =IF(E10="","N/A",IF(E10<0.2,"Low Discount",IF(E10<=0.4,"Medium Discount","High Discount"))) -> High Discount | G10: 5 | H10: 4.8 | I10: excellent | J10: =IF(H10="","N/A",IF(H10<3,"Poor",IF(H10<4.5,"Average","Excellent"))) -> Excellent | K10: =F10 -> High Discount
A11: 40cm Gold DIY Acrylic Wall Sticker Clock | B11: 552 | C11: 1035 | D11: =C11-B11 -> 483 | E11: =IF(C11>0,(C11-B11)/C11,0) -> 0.46666667 | F11: =IF(E11="","N/A",IF(E11<0.2,"Low Discount",IF(E11<=0.4,"Medium Discount","High Discount"))) -> High Discount | G11: 12 | H11: 4.8 | I11: excellent | J11: =IF(H11="","N/A",IF(H11<3,"Poor",IF(H11<4.5,"Average","Excellent"))) -> Excellent | K11: =F11 -> High Discount
A12: Weighing Scale Digital Bathroom Body Fat Scale USB-Black | B12: 1580 | C12: 2499 | D12: =C12-B12 -> 919 | E12: =IF(C12>0,(C12-B12)/C12,0) -> 0.3677471 | F12: =IF(E12="","N/A",IF(E12<0.2,"Low Discount",IF(E12<=0.4,"Medium Discount","High Discount"))) -> Medium Discount | G12: 7 | H12: 4.7 | I12: excellent | J12: =IF(H12="","N/A",IF(H12<3,"Poor",IF(H12<4.5,"Average","Excellent"))) -> Excellent | K12: =F12 -> Medium Discount
A13: 100 Pcs Crochet Hook Tool Set Knitting Hook Set With Box | B13: 990 | C13: 1500 | D13: =C13-B13 -> 510 | E13: =IF(C13>0,(C13-B13)/C13,0) -> 0.34 | F13: =IF(E13="","N/A",IF(E13<0.2,"Low Discount",IF(E13<=0.4,"Medium Discount","High Discount"))) -> Medium Discount | G13: 39 | H13: 4.7 | I13: excellent | J13: =IF(H13="","N/A",IF(H13<3,"Poor",IF(H13<4.5,"Average","Excellent"))) -> Excellent | K13: =F13 -> Medium Discount
... A57: Wall-mounted Sticker Punch-free Plug Fixer | B57: 450 | C57: 900 | D57: =C57-B57 -> 450 | E57: =IF(C57>0,(C57-B57)/C57,0) -> 0.5 | F57: =IF(E57="","N/A",IF(E57<0.2,"Low Discount",IF(E57<=0.4,"Medium Discount","High Discount"))) -> High Discount | G57: 1 | H57: 2 | I57: poor | J57: =IF(H57="","N/A",IF(H57<3,"Poor",IF(H57<4.5,"Average","Excellent"))) -> Poor | K57: =F57 -> High Discount
A58: 4pcs Bathroom/Kitchen Towel Rack,Roll Paper Holder,Towel Bars,Hook | B58: 1860 | C58: 3220 | D58: =C58-B58 -> 1360 | E58: =IF(C58>0,(C58-B58)/C58,0) -> 0.42236025 | F58: =IF(E58="","N/A",IF(E58<0.2,"Low Discount",IF(E58<=0.4,"Medium Discount","High Discount"))) -> High Discount | J58: =IF(H58="","N/A",IF(H58<3,"Poor",IF(H58<4.5,"Average","Excellent"))) -> N/A | K58: =F58 -> High Discount
A59: MultiFunctional Storage Rack Multi-layer Bookshelf | B59: 2200 | C59: 4080 | D59: =C59-B59 -> 1880 | E59: =IF(C59>0,(C59-B59)/C59,0) -> 0.46078431 | F59: =IF(E59="","N/A",IF(E59<0.2,"Low Discount",IF(E59<=0.4,"Medium Discount","High Discount"))) -> High Discount | J59: =IF(H59="","N/A",IF(H59<3,"Poor",IF(H59<4.5,"Average","Excellent"))) -> N/A | K59: =F59 -> High Discount
A60: LASA Stainless Steel Double Wall Mount Soap Dispenser - 500ml | B60: 2750 | C60: 4471 | D60: =C60-B60 -> 1721 | E60: =IF(C60>0,(C60-B60)/C60,0) -> 0.38492507 | F60: =IF(E60="","N/A",IF(E60<0.2,"Low Discount",IF(E60<=0.4,"Medium Discount","High Discount"))) -> Medium Discount | J60: =IF(H60="","N/A",IF(H60<3,"Poor",IF(H60<4.5,"Average","Excellent"))) -> N/A | K60: =F60 -> Medium Discount
A61: 4M Float Switch Water Level Controller -Water Tank | B61: 475 | C61: 931 | D61: =C61-B61 -> 456 | E61: =IF(C61>0,(C61-B61)/C61,0) -> 0.48979592 | F61: =IF(E61="","N/A",IF(E61<0.2,"Low Discount",IF(E61<=0.4,"Medium Discount","High Discount"))) -> High Discount | J61: =IF(H61="","N/A",IF(H61<3,"Poor",IF(H61<4.5,"Average","Excellent"))) -> N/A | K61: =F61 -> High Discount
A62: Modern Sofa Throw Pillow Cover-45x45cm-Blue&Red | B62: 238 | C62: 476 | D62: =C62-B62 -> 238 | E62: =IF(C62>0,(C62-B62)/C62,0) -> 0.5 | F62: =IF(E62="","N/A",IF(E62<0.2,"Low Discount",IF(E62<=0.4,"Medium Discount","High Discount"))) -> High Discount | J62: =IF(H62="","N/A",IF(H62<3,"Poor",IF(H62<4.5,"Average","Excellent"))) -> N/A | K62: =F62 -> High Discount
A63: Balloon Insert, Birthday Party Balloon Set, PU Leather | B63: 610 | C63: 1060 | D63: =C63-B63 -> 450 | E63: =IF(C63>0,(C63-B63)/C63,0) -> 0.4245283 | F63: =IF(E63="","N/A",IF(E63<0.2,"Low Discount",IF(E63<=0.4,"Medium Discount","High Discount"))) -> High Discount | J63: =IF(H63="","N/A",IF(H63<3,"Poor",IF(H63<4.5,"Average","Excellent"))) -> N/A | K63: =F63 -> High Discount
A64: Shower Cap Wide Elastic Band Cover Reusable Bashroom Cap | B64: 2132 | C64: 2169 | D64: =C64-B64 -> 37 | E64: =IF(C64>0,(C64-B64)/C64,0) -> 0.017058552 | F64: =IF(E64="","N/A",IF(E64<0.2,"Low Discount",IF(E64<=0.4,"Medium Discount","High Discount"))) -> Low Discount | J64: =IF(H64="","N/A",IF(H64<3,"Poor",IF(H64<4.5,"Average","Excellent"))) -> N/A | K64: =F64 -> Low Discount
A65: Christmas Elk Fence Yard Lawn Decorations Cute For Holidays | B65: 999 | C65: 2000 | D65: =C65-B65 -> 1001 | E65: =IF(C65>0,(C65-B65)/C65,0) -> 0.5005 | F65: =IF(E65="","N/A",IF(E65<0.2,"Low Discount",IF(E65<=0.4,"Medium Discount","High Discount"))) -> High Discount | J65: =IF(H65="","N/A",IF(H65<3,"Poor",IF(H65<4.5,"Average","Excellent"))) -> N/A | K65: =F65 -> High Discount
A66: 60W Hot Melt Glue Sprayer - Efficient And Stable Glue Dispensing | B66: 1190 | C66: 1785 | D66: =C66-B66 -> 595 | E66: =IF(C66>0,(C66-B66)/C66,0) -> 0.33333333 | F66: =IF(E66="","N/A",IF(E66<0.2,"Low Discount",IF(E66<=0.4,"Medium Discount","High Discount"))) -> Medium Discount | J66: =IF(H66="","N/A",IF(H66<3,"Poor",IF(H66<4.5,"Average","Excellent"))) -> N/A | K66: =F66 -> Medium Discount
A67: Car Phone Charging Stand | B67: 671 | C67: 1316 | D67: =C67-B67 -> 645 | E67: =IF(C67>0,(C67-B67)/C67,0) -> 0.49012158 | F67: =IF(E67="","N/A",IF(E67<0.2,"Low Discount",IF(E67<=0.4,"Medium Discount","High Discount"))) -> High Discount | J67: =IF(H67="","N/A",IF(H67<3,"Poor",IF(H67<4.5,"Average","Excellent"))) -> N/A | K67: =F67 -> High Discount
A68: 2pcs Solar Street Light Flood Light Outdoor | B68: 1200 | C68: 1950 | D68: =C68-B68 -> 750 | E68: =IF(C68>0,(C68-B68)/C68,0) -> 0.38461538 | F68: =IF(E68="","N/A",IF(E68<0.2,"Low Discount",IF(E68<=0.4,"Medium Discount","High Discount"))) -> Medium Discount | J68: =IF(H68="","N/A",IF(H68<3,"Poor",IF(H68<4.5,"Average","Excellent"))) -> N/A | K68: =F68 -> Medium Discount
A69: Creative Owl Shape Keychain Black | B69: 199 | C69: 504 | D69: =C69-B69 -> 305 | E69: =IF(C69>0,(C69-B69)/C69,0) -> 0.60515873 | F69: =IF(E69="","N/A",IF(E69<0.2,"Low Discount",IF(E69<=0.4,"Medium Discount","High Discount"))) -> High Discount | J69: =IF(H69="","N/A",IF(H69<3,"Poor",IF(H69<4.5,"Average","Excellent"))) -> N/A | K69: =F69 -> High Discount
... A112: Black Simple Water Cup Wine Coaster Anti Slip Absorbent | B112: 169 | C112: 320 | D112: =C112-B112 -> 151 | E112: =IF(C112>0,(C112-B112)/C112,0) -> 0.471875 | F112: =IF(E112="","N/A",IF(E112<0.2,"Low Discount",IF(E112<=0.4,"Medium Discount","High Discount"))) -> High Discount | J112: =IF(H112="","N/A",IF(H112<3,"Poor",IF(H112<4.5,"Average","Excellent"))) -> N/A | K112: =F112 -> High Discount

Sheet Dashboard
B1: JUMIA PRODUCTS — INTERACTIVE ANALYTICS DASHBOARD
B4: TOTAL PRODUCTS | D4: AVG PRICE | F4: AVG DISCOUNT | H4: AVG RATING | J4: TOTAL REVIEWS | L4: HIGH DISCOUNT
B5: =COUNTA('Cleaned Data'!A2:A112) -> 111 | D5: =ROUND(AVERAGE('Cleaned Data'!B2:B112),0) -> 1181 | F5: =ROUND(AVERAGE('Cleaned Data'!E2:E112)*100,1) -> 36.7 | H5: =ROUND(AVERAGEIF('Cleaned Data'!H2:H112,"<>",'Cleaned Data'!H2:H112),2) -> 3.88 | J5: =SUM('Cleaned Data'!G2:G112) -> 721 | L5: =COUNTIF('Cleaned Data'!F2:F112,"High Discount") -> 62
D7: KES | F7: % off | H7: / 5 | L7: products
B10: PRODUCTS BY RATING CATEGORY | H10: PRODUCTS BY DISCOUNT CATEGORY
B11: Category | C11: # Products | D11: Avg Price (KES) | E11: Avg Disc % | F11: Avg Reviews | H11: Category | I11: # Products | J11: Avg Price (KES) | K11: Avg Rating | L11: Avg Reviews
B12: Excellent | C12: =COUNTIF('Cleaned Data'!$J$2:$J$112,"Excellent") -> 22 | D12: =AVERAGEIF('Cleaned Data'!$J$2:$J$112,"Excellent",'Cleaned Data'!$B$2:$B$112) -> 1381.0909 | E12: =AVERAGEIF('Cleaned Data'!$J$2:$J$112,"Excellent",'Cleaned Data'!$E$2:$E$112) -> 0.37499008 | F12: =AVERAGEIF('Cleaned Data'!$J$2:$J$112,"Excellent",'Cleaned Data'!$G$2:$G$112) -> 14.954545 | H12: High Discount | I12: =COUNTIF('Cleaned Data'!$F$2:$F$112,"High Discount") -> 62 | J12: =AVERAGEIF('Cleaned Data'!$F$2:$F$112,"High Discount",'Cleaned Data'!$B$2:$B$112) -> 756.41935 | K12: =AVERAGEIF('Cleaned Data'!$F$2:$F$112,"High Discount",'Cleaned Data'!$H$2:$H$112) -> 3.6133333 | L12: =AVERAGEIF('Cleaned Data'!$F$2:$F$112,"High Discount",'Cleaned Data'!$G$2:$G$112) -> 11.133333
B13: Average | C13: =COUNTIF('Cleaned Data'!$J$2:$J$112,"Average") -> 22 | D13: =AVERAGEIF('Cleaned Data'!$J$2:$J$112,"Average",'Cleaned Data'!$B$2:$B$112) -> 1369.4091 | E13: =AVERAGEIF('Cleaned Data'!$J$2:$J$112,"Average",'Cleaned Data'!$E$2:$E$112) -> 0.38033104 | F13: =AVERAGEIF('Cleaned Data'!$J$2:$J$112,"Average",'Cleaned Data'!$G$2:$G$112) -> 10.136364 | H13: Medium Discount | I13: =COUNTIF('Cleaned Data'!$F$2:$F$112,"Medium Discount") -> 31 | J13: =AVERAGEIF('Cleaned Data'!$F$2:$F$112,"Medium Discount",'Cleaned Data'!$B$2:$B$112) -> 1579.6452 | K13: =AVERAGEIF('Cleaned Data'!$F$2:$F$112,"Medium Discount",'Cleaned Data'!$H$2:$H$112) -> 4.2681818 | L13: =AVERAGEIF('Cleaned Data'!$F$2:$F$112,"Medium Discount",'Cleaned Data'!$G$2:$G$112) -> 15.863636
B14: Poor | C14: =COUNTIF('Cleaned Data'!$J$2:$J$112,"Poor") -> 12 | D14: =AVERAGEIF('Cleaned Data'!$J$2:$J$112,"Poor",'Cleaned Data'!$B$2:$B$112) -> 998.33333 | E14: =AVERAGEIF('Cleaned Data'!$J$2:$J$112,"Poor",'Cleaned Data'!$E$2:$E$112) -> 0.43217789 | F14: =AVERAGEIF('Cleaned Data'!$J$2:$J$112,"Poor",'Cleaned Data'!$G$2:$G$112) -> 14.083333 | H14: Low Discount | I14: =COUNTIF('Cleaned Data'!$F$2:$F$112,"Low Discount") -> 18 | J14: =AVERAGEIF('Cleaned Data'!$F$2:$F$112,"Low Discount",'Cleaned Data'!$B$2:$B$112) -> 1959.1667 | K14: =AVERAGEIF('Cleaned Data'!$F$2:$F$112,"Low Discount",'Cleaned Data'!$H$2:$H$112) -> 3.725 | L14: =AVERAGEIF('Cleaned Data'!$F$2:$F$112,"Low Discount",'Cleaned Data'!$G$2:$G$112) -> 9.5
B15: N/A | C15: =COUNTIF('Cleaned Data'!$J$2:$J$112,"N/A") -> 55 | D15: =AVERAGEIF('Cleaned Data'!$J$2:$J$112,"N/A",'Cleaned Data'!$B$2:$B$112) -> 1066.2 | E15: =AVERAGEIF('Cleaned Data'!$J$2:$J$112,"N/A",'Cleaned Data'!$E$2:$E$112) -> 0.34515064 | F15: =IFERROR(AVERAGEIF('Cleaned Data'!$J$2:$J$112,"N/A",'Cleaned Data'!$G$2:$G$112),"N/A") -> N/A
B17: HIGH vs LOW DISCOUNT — PERFORMANCE COMPARISON | G17: TREND ANALYSIS — DISCOUNT RANGE vs REVIEWS & RATING
B18: Metric | C18: High Discount | D18: Low Discount | E18: Difference | G18: Discount Range | H18: # Products | I18: Avg Reviews | J18: Avg Rating
B19: # Products | C19: =COUNTIF('Cleaned Data'!$F$2:$F$112,"High Discount") -> 62 | D19: =COUNTIF('Cleaned Data'!$F$2:$F$112,"Low Discount") -> 18 | E19: =C19-D19 -> 44 | G19: <20% | H19: =COUNTIFS('Cleaned Data'!$E$2:$E$112,">=0",'Cleaned Data'!$E$2:$E$112,"<0.2") -> 18 | I19: =AVERAGEIFS('Cleaned Data'!$G$2:$G$112,'Cleaned Data'!$E$2:$E$112,">=0",'Cleaned Data'!$E$2:$E$112,"<0.2") -> 9.5 | J19: =AVERAGEIFS('Cleaned Data'!$H$2:$H$112,'Cleaned Data'!$E$2:$E$112,">=0",'Cleaned Data'!$E$2:$E$112,"<0.2") -> 3.725
B20: Avg Price (KES) | C20: =AVERAGEIF('Cleaned Data'!$F$2:$F$112,"High Discount",'Cleaned Data'!$B$2:$B$112) -> 756.41935 | D20: =AVERAGEIF('Cleaned Data'!$F$2:$F$112,"Low Discount",'Cleaned Data'!$B$2:$B$112) -> 1959.1667 | E20: =C20-D20 -> -1202.7473 | G20: 20-30% | H20: =COUNTIFS('Cleaned Data'!$E$2:$E$112,">=0.2",'Cleaned Data'!$E$2:$E$112,"<0.3") -> 14 | I20: =AVERAGEIFS('Cleaned Data'!$G$2:$G$112,'Cleaned Data'!$E$2:$E$112,">=0.2",'Cleaned Data'!$E$2:$E$112,"<0.3") -> 18.545455 | J20: =AVERAGEIFS('Cleaned Data'!$H$2:$H$112,'Cleaned Data'!$E$2:$E$112,">=0.2",'Cleaned Data'!$E$2:$E$112,"<0.3") -> 4.2454545
B21: Avg Discount % | C21: =AVERAGEIF('Cleaned Data'!$F$2:$F$112,"High Discount",'Cleaned Data'!$E$2:$E$112) -> 0.48317809 | D21: =AVERAGEIF('Cleaned Data'!$F$2:$F$112,"Low Discount",'Cleaned Data'!$E$2:$E$112) -> 0.072275923 | E21: =C21-D21 -> 0.41090217 | G21: 30-40% | H21: =COUNTIFS('Cleaned Data'!$E$2:$E$112,">=0.3",'Cleaned Data'!$E$2:$E$112,"<0.4") -> 17 | I21: =AVERAGEIFS('Cleaned Data'!$G$2:$G$112,'Cleaned Data'!$E$2:$E$112,">=0.3",'Cleaned Data'!$E$2:$E$112,"<0.4") -> 13.181818 | J21: =AVERAGEIFS('Cleaned Data'!$H$2:$H$112,'Cleaned Data'!$E$2:$E$112,">=0.3",'Cleaned Data'!$E$2:$E$112,"<0.4") -> 4.2909091
B22: Avg Rating | C22: =AVERAGEIF('Cleaned Data'!$F$2:$F$112,"High Discount",'Cleaned Data'!$H$2:$H$112) -> 3.6133333 | D22: =AVERAGEIF('Cleaned Data'!$F$2:$F$112,"Low Discount",'Cleaned Data'!$H$2:$H$112) -> 3.725 | E22: =C22-D22 -> -0.11166667 | G22: 40-50% | H22: =COUNTIFS('Cleaned Data'!$E$2:$E$112,">=0.4",'Cleaned Data'!$E$2:$E$112,"<0.5") -> 43 | I22: =AVERAGEIFS('Cleaned Data'!$G$2:$G$112,'Cleaned Data'!$E$2:$E$112,">=0.4",'Cleaned Data'!$E$2:$E$112,"<0.5") -> 13.157895 | J22: =AVERAGEIFS('Cleaned Data'!$H$2:$H$112,'Cleaned Data'!$E$2:$E$112,">=0.4",'Cleaned Data'!$E$2:$E$112,"<0.5") -> 3.6631579
B23: Avg Reviews | C23: =AVERAGEIF('Cleaned Data'!$F$2:$F$112,"High Discount",'Cleaned Data'!$G$2:$G$112) -> 11.133333 | D23: =AVERAGEIF('Cleaned Data'!$F$2:$F$112,"Low Discount",'Cleaned Data'!$G$2:$G$112) -> 9.5 | E23: =C23-D23 -> 1.6333333 | G23: >50% | H23: =COUNTIFS('Cleaned Data'!$E$2:$E$112,">=0.5",'Cleaned Data'!$E$2:$E$112,"<1.0") -> 19 | I23: =AVERAGEIFS('Cleaned Data'!$G$2:$G$112,'Cleaned Data'!$E$2:$E$112,">=0.5",'Cleaned Data'!$E$2:$E$112,"<1.0") -> 7.6363636 | J23: =AVERAGEIFS('Cleaned Data'!$H$2:$H$112,'Cleaned Data'!$E$2:$E$112,">=0.5",'Cleaned Data'!$E$2:$E$112,"<1.0") -> 3.5272727

Sheet PivotTables
B1: PIVOT TABLES
B3: PIVOT TABLE 1: BY DISCOUNT CATEGORY | I3: PIVOT TABLE 2: BY RATING CATEGORY
B4: Discount Label | C4: Count | D4: Avg Price (KES) | E4: Avg Rating | F4: Avg Reviews | I4: Rating Category | J4: Count | K4: Avg Price (KES) | L4: Avg Disc % | M4: Avg Reviews
B5: High Discount | C5: =GETPIVOTDATA("Sum of # Products",'Discount Pivot'!$A$3,"Discount Category","High Discount") -> 62 | D5: =AVERAGEIF(PivotSource!$F$2:$F$112,"High Discount",PivotSource!$B$2:$B$112) -> 756.41935 | E5: =AVERAGEIF(PivotSource!$F$2:$F$112,"High Discount",PivotSource!$H$2:$H$112) -> 3.6133333 | F5: =AVERAGEIF(PivotSource!$F$2:$F$112,"High Discount",PivotSource!$G$2:$G$112) -> 11.133333 | I5: Excellent | J5: =COUNTIF(PivotSource!$J$2:$J$112,"Excellent") -> 22 | K5: =AVERAGEIF(PivotSource!$J$2:$J$112,"Excellent",PivotSource!$B$2:$B$112) -> 1381.0909 | L5: =AVERAGEIF(PivotSource!$J$2:$J$112,"Excellent",PivotSource!$E$2:$E$112) -> 0.37499008 | M5: =AVERAGEIF(PivotSource!$J$2:$J$112,"Excellent",PivotSource!$G$2:$G$112) -> 14.954545
B6: Medium Discount | C6: =GETPIVOTDATA("Sum of # Products",'Discount Pivot'!$A$3,"Discount Category","Medium Discount") -> 31 | D6: =AVERAGEIF(PivotSource!$F$2:$F$112,"Medium Discount",PivotSource!$B$2:$B$112) -> 1579.6452 | E6: =AVERAGEIF(PivotSource!$F$2:$F$112,"Medium Discount",PivotSource!$H$2:$H$112) -> 4.2681818 | F6: =AVERAGEIF(PivotSource!$F$2:$F$112,"Medium Discount",PivotSource!$G$2:$G$112) -> 15.863636 | I6: Average | J6: =COUNTIF(PivotSource!$J$2:$J$112,"Average") -> 22 | K6: =AVERAGEIF(PivotSource!$J$2:$J$112,"Average",PivotSource!$B$2:$B$112) -> 1369.4091 | L6: =AVERAGEIF(PivotSource!$J$2:$J$112,"Average",PivotSource!$E$2:$E$112) -> 0.38033104 | M6: =AVERAGEIF(PivotSource!$J$2:$J$112,"Average",PivotSource!$G$2:$G$112) -> 10.136364
B7: Low Discount | C7: =GETPIVOTDATA("Sum of # Products",'Discount Pivot'!$A$3,"Discount Category","Low Discount") -> 18 | D7: =AVERAGEIF(PivotSource!$F$2:$F$112,"Low Discount",PivotSource!$B$2:$B$112) -> 1959.1667 | E7: =AVERAGEIF(PivotSource!$F$2:$F$112,"Low Discount",PivotSource!$H$2:$H$112) -> 3.725 | F7: =AVERAGEIF(PivotSource!$F$2:$F$112,"Low Discount",PivotSource!$G$2:$G$112) -> 9.5 | I7: Poor | J7: =COUNTIF(PivotSource!$J$2:$J$112,"Poor") -> 12 | K7: =AVERAGEIF(PivotSource!$J$2:$J$112,"Poor",PivotSource!$B$2:$B$112) -> 998.33333 | L7: =AVERAGEIF(PivotSource!$J$2:$J$112,"Poor",PivotSource!$E$2:$E$112) -> 0.43217789 | M7: =AVERAGEIF(PivotSource!$J$2:$J$112,"Poor",PivotSource!$G$2:$G$112) -> 14.083333
B8: Grand Total | C8: =SUM(C5:C7) -> 111 | D8: =AVERAGE(PivotSource!$B$2:$B$112) -> 1181.3694 | E8: =AVERAGEIF(PivotSource!$H$2:$H$112,"<>",PivotSource!$H$2:$H$112) -> 3.8785714 | F8: =AVERAGEIF(PivotSource!$G$2:$G$112,"<>",PivotSource!$G$2:$G$112) -> 12.875 | I8: N/A (No Reviews) | J8: =COUNTIF(PivotSource!$J$2:$J$112,"N/A") -> 55 | K8: =AVERAGEIF(PivotSource!$J$2:$J$112,"N/A",PivotSource!$B$2:$B$112) -> 1066.2 | L8: "" | M8: ""
I9: Grand Total | J9: =SUM(J5:J8) -> 111 | K9: =AVERAGE(PivotSource!$B$2:$B$112) -> 1181.3694 | L9: =AVERAGE(PivotSource!$E$2:$E$112) -> 0.36744581 | M9: =AVERAGEIF(PivotSource!$G$2:$G$112,"<>",PivotSource!$G$2:$G$112) -> 12.875
B11: PIVOT TABLE 3: DISCOUNT RANGE vs REVIEWS & RATINGS (Trend Analysis) | K11: PIVOT TABLE 4: CROSS-ANALYSIS — Rating Category × Discount Label (Count of Products)
B12: Discount Range | C12: Min Disc% | D12: Max Disc% | E12: # Products | F12: Avg Price | G12: Avg Disc% | H12: Avg Reviews | I12: Avg Rating | K12: Rating \ Discount | L12: High Discount | M12: Medium Discount | N12: Low Discount | O12: Row Total
B13: <20% | C13: 0 | D13: 0.2 | E13: =COUNTIFS(PivotSource!$E$2:$E$112,">=0",PivotSource!$E$2:$E$112,"<0.2") -> 18 | F13: =AVERAGEIFS(PivotSource!$B$2:$B$112,PivotSource!$E$2:$E$112,">=0",PivotSource!$E$2:$E$112,"<0.2") -> 1959.1667 | G13: =AVERAGEIFS(PivotSource!$E$2:$E$112,PivotSource!$E$2:$E$112,">=0",PivotSource!$E$2:$E$112,"<0.2") -> 0.072275923 | H13: =AVERAGEIFS(PivotSource!$G$2:$G$112,PivotSource!$E$2:$E$112,">=0",PivotSource!$E$2:$E$112,"<0.2") -> 9.5 | I13: =AVERAGEIFS(PivotSource!$H$2:$H$112,PivotSource!$E$2:$E$112,">=0",PivotSource!$E$2:$E$112,"<0.2") -> 3.725 | K13: Excellent | L13: =COUNTIFS(PivotSource!$J$2:$J$112,"Excellent",PivotSource!$F$2:$F$112,"High Discount") -> 9 | M13: =COUNTIFS(PivotSource!$J$2:$J$112,"Excellent",PivotSource!$F$2:$F$112,"Medium Discount") -> 12 | N13: =COUNTIFS(PivotSource!$J$2:$J$112,"Excellent",PivotSource!$F$2:$F$112,"Low Discount") -> 1 | O13: =COUNTIF(PivotSource!$J$2:$J$112,"Excellent") -> 22
B14: 20–30% | C14: 0.2 | D14: 0.3 | E14: =COUNTIFS(PivotSource!$E$2:$E$112,">=0.2",PivotSource!$E$2:$E$112,"<0.3") -> 14 | F14: =AVERAGEIFS(PivotSource!$B$2:$B$112,PivotSource!$E$2:$E$112,">=0.2",PivotSource!$E$2:$E$112,"<0.3") -> 1774.3571 | G14: =AVERAGEIFS(PivotSource!$E$2:$E$112,PivotSource!$E$2:$E$112,">=0.2",PivotSource!$E$2:$E$112,"<0.3") -> 0.24608994 | H14: =AVERAGEIFS(PivotSource!$G$2:$G$112,PivotSource!$E$2:$E$112,">=0.2",PivotSource!$E$2:$E$112,"<0.3") -> 18.545455 | I14: =AVERAGEIFS(PivotSource!$H$2:$H$112,PivotSource!$E$2:$E$112,">=0.2",PivotSource!$E$2:$E$112,"<0.3") -> 4.2454545 | K14: Average | L14: =COUNTIFS(PivotSource!$J$2:$J$112,"Average",PivotSource!$F$2:$F$112,"High Discount") -> 11 | M14: =COUNTIFS(PivotSource!$J$2:$J$112,"Average",PivotSource!$F$2:$F$112,"Medium Discount") -> 9 | N14: =COUNTIFS(PivotSource!$J$2:$J$112,"Average",PivotSource!$F$2:$F$112,"Low Discount") -> 2 | O14: =COUNTIF(PivotSource!$J$2:$J$112,"Average") -> 22
B15: 30–40% | C15: 0.3 | D15: 0.4 | E15: =COUNTIFS(PivotSource!$E$2:$E$112,">=0.3",PivotSource!$E$2:$E$112,"<0.4") -> 17 | F15: =AVERAGEIFS(PivotSource!$B$2:$B$112,PivotSource!$E$2:$E$112,">=0.3",PivotSource!$E$2:$E$112,"<0.4") -> 1419.2941 | G15: =AVERAGEIFS(PivotSource!$E$2:$E$112,PivotSource!$E$2:$E$112,">=0.3",PivotSource!$E$2:$E$112,"<0.4") -> 0.35783631 | H15: =AVERAGEIFS(PivotSource!$G$2:$G$112,PivotSource!$E$2:$E$112,">=0.3",PivotSource!$E$2:$E$112,"<0.4") -> 13.181818 | I15: =AVERAGEIFS(PivotSource!$H$2:$H$112,PivotSource!$E$2:$E$112,">=0.3",PivotSource!$E$2:$E$112,"<0.4") -> 4.2909091 | K15: Poor | L15: =COUNTIFS(PivotSource!$J$2:$J$112,"Poor",PivotSource!$F$2:$F$112,"High Discount") -> 10 | M15: =COUNTIFS(PivotSource!$J$2:$J$112,"Poor",PivotSource!$F$2:$F$112,"Medium Discount") -> 1 | N15: =COUNTIFS(PivotSource!$J$2:$J$112,"Poor",PivotSource!$F$2:$F$112,"Low Discount") -> 1 | O15: =COUNTIF(PivotSource!$J$2:$J$112,"Poor") -> 12
B16: 40–50% | C16: 0.4 | D16: 0.5 | E16: =COUNTIFS(PivotSource!$E$2:$E$112,">=0.4",PivotSource!$E$2:$E$112,"<0.5") -> 43 | F16: =AVERAGEIFS(PivotSource!$B$2:$B$112,PivotSource!$E$2:$E$112,">=0.4",PivotSource!$E$2:$E$112,"<0.5") -> 793.46512 | G16: =AVERAGEIFS(PivotSource!$E$2:$E$112,PivotSource!$E$2:$E$112,">=0.4",PivotSource!$E$2:$E$112,"<0.5") -> 0.46225844 | H16: =AVERAGEIFS(PivotSource!$G$2:$G$112,PivotSource!$E$2:$E$112,">=0.4",PivotSource!$E$2:$E$112,"<0.5") -> 13.157895 | I16: =AVERAGEIFS(PivotSource!$H$2:$H$112,PivotSource!$E$2:$E$112,">=0.4",PivotSource!$E$2:$E$112,"<0.5") -> 3.6631579 | K16: N/A | L16: =COUNTIFS(PivotSource!$J$2:$J$112,"N/A",PivotSource!$F$2:$F$112,"High Discount") -> 32 | M16: =COUNTIFS(PivotSource!$J$2:$J$112,"N/A",PivotSource!$F$2:$F$112,"Medium Discount") -> 9 | N16: =COUNTIFS(PivotSource!$J$2:$J$112,"N/A",PivotSource!$F$2:$F$112,"Low Discount") -> 14 | O16: =COUNTIF(PivotSource!$J$2:$J$112,"N/A") -> 55
B17: >50% | C17: 0.5 | D17: 1 | E17: =COUNTIFS(PivotSource!$E$2:$E$112,">=0.5",PivotSource!$E$2:$E$112,"<1.0") -> 19 | F17: =AVERAGEIFS(PivotSource!$B$2:$B$112,PivotSource!$E$2:$E$112,">=0.5",PivotSource!$E$2:$E$112,"<1.0") -> 672.57895 | G17: =AVERAGEIFS(PivotSource!$E$2:$E$112,PivotSource!$E$2:$E$112,">=0.5",PivotSource!$E$2:$E$112,"<1.0") -> 0.53052257 | H17: =AVERAGEIFS(PivotSource!$G$2:$G$112,PivotSource!$E$2:$E$112,">=0.5",PivotSource!$E$2:$E$112,"<1.0") -> 7.6363636 | I17: =AVERAGEIFS(PivotSource!$H$2:$H$112,PivotSource!$E$2:$E$112,">=0.5",PivotSource!$E$2:$E$112,"<1.0") -> 3.5272727 | K17: Col Total | L17: =COUNTIF(PivotSource!$F$2:$F$112,"High Discount") -> 62 | M17: =COUNTIF(PivotSource!$F$2:$F$112,"Medium Discount") -> 31 | N17: =COUNTIF(PivotSource!$F$2:$F$112,"Low Discount") -> 18 | O17: =SUM(L17:N17) -> 111
B18: Grand Total | E18: =SUM(E13:E17) -> 111 | F18: =AVERAGE(PivotSource!$B$2:$B$112) -> 1181.3694 | G18: =AVERAGE(PivotSource!$E$2:$E$112) -> 0.36744581 | H18: =AVERAGEIF(PivotSource!$G$2:$G$112,"<>",PivotSource!$G$2:$G$112) -> 12.875 | I18: =AVERAGEIF(PivotSource!$H$2:$H$112,"<>",PivotSource!$H$2:$H$112) -> 3.8785714

Sheet Analysis
A1: DESCRIPTIVE STATISTICS — Formulas & Cell References
A2: Metric | B2: Function Used | C2: Result
A3: Total Products | B3: COUNTA | C3: =COUNTA('Cleaned Data'!A2:A112) -> 111
A4: Avg Current Price (KES) | B4: AVERAGE | C4: =AVERAGE('Cleaned Data'!B2:B112) -> 1181.3694
A5: Avg Old Price (KES) | B5: AVERAGE | C5: =AVERAGE('Cleaned Data'!C2:C112) -> 1803.0991
A6: Avg Discount % | B6: AVERAGE | C6: =AVERAGE('Cleaned Data'!E2:E112) -> 0.36744581
A7: Avg Rating (reviewed only) | B7: AVERAGEIF | C7: =AVERAGEIF('Cleaned Data'!H2:H112,"<>",'Cleaned Data'!H2:H112) -> 3.8785714
A8: Total Reviews | B8: SUM | C8: =SUM('Cleaned Data'!G2:G112) -> 721
A9: Max Current Price (KES) | B9: MAX | C9: =MAX('Cleaned Data'!B2:B112) -> 3750
A10: Min Current Price (KES) | B10: MIN | C10: =MIN('Cleaned Data'!B2:B112) -> 38
A11: Most Expensive Product | B11: INDEX/MATCH | C11: =INDEX('Cleaned Data'!A2:A112,MATCH(MAX('Cleaned Data'!B2:B112),'Cleaned Data'!B2:B112,0)) -> 32PCS Portable Cordless Drill Set With Cyclic Battery Drive -26 Variable Speed
A12: Least Expensive Product | B12: INDEX/MATCH | C12: =INDEX('Cleaned Data'!A2:A112,MATCH(MIN('Cleaned Data'!B2:B112),'Cleaned Data'!B2:B112,0)) -> 3PCS Single Head Knitting Crochet Sweater Needle Set
A13: Avg Disc% – High Discount | B13: AVERAGEIF | C13: =AVERAGEIF('Cleaned Data'!F2:F112,"High Discount",'Cleaned Data'!E2:E112) -> 0.48317809
A14: Avg Rating – High Discount | B14: AVERAGEIF | C14: =AVERAGEIF('Cleaned Data'!F2:F112,"High Discount",'Cleaned Data'!H2:H112) -> 3.6133333
A15: Avg Rating – Low Discount | B15: AVERAGEIF | C15: =AVERAGEIF('Cleaned Data'!F2:F112,"Low Discount",'Cleaned Data'!H2:H112) -> 3.725
A16: Avg Reviews – High Discount | B16: AVERAGEIF | C16: =AVERAGEIF('Cleaned Data'!F2:F112,"High Discount",'Cleaned Data'!G2:G112) -> 11.133333
A17: Avg Reviews – Low Discount | B17: AVERAGEIF | C17: =AVERAGEIF('Cleaned Data'!F2:F112,"Low Discount",'Cleaned Data'!G2:G112) -> 9.5
A18: Products with No Reviews | B18: COUNTBLANK | C18: =COUNTBLANK('Cleaned Data'!G2:G112) -> 55
A19: # Excellent Rated | B19: COUNTIF | C19: =COUNTIF('Cleaned Data'!J2:J112,"Excellent") -> 22
A20: # Average Rated | B20: COUNTIF | C20: =COUNTIF('Cleaned Data'!J2:J112,"Average") -> 22
A21: # Poor Rated | B21: COUNTIF | C21: =COUNTIF('Cleaned Data'!J2:J112,"Poor") -> 12
A22: # High Discount Products | B22: COUNTIF | C22: =COUNTIF('Cleaned Data'!F2:F112,"High Discount") -> 62
A23: # Medium Discount Products | B23: COUNTIF | C23: =COUNTIF('Cleaned Data'!F2:F112,"Medium Discount") -> 31
A24: # Low Discount Products | B24: COUNTIF | C24: =COUNTIF('Cleaned Data'!F2:F112,"Low Discount") -> 18
A26: TOP 5 HIGHEST RATED PRODUCTS
A27: Rank | B27: Product | C27: Rating
A28: 1 | B28: =IFERROR(INDEX('Cleaned Data'!$A$2:$A$112,MATCH(LARGE(IF('Cleaned Data'!$H$2:$H$112<>"",'Cleaned Data'!$H$2:$H$112),1),'Cleaned Data'!$H$2:$H$112,0)),"N/A") -> Anti-Skid Absorbent Insulation Coaster For Home Office | C28: =LARGE(IF('Cleaned Data'!$H$2:$H$112<>"",'Cleaned Data'!$H$2:$H$112),1) -> 5
A29: 2 | B29: =IFERROR(INDEX('Cleaned Data'!$A$2:$A$112,MATCH(LARGE(IF('Cleaned Data'!$H$2:$H$112<>"",'Cleaned Data'!$H$2:$H$112),2),'Cleaned Data'!$H$2:$H$112,0)),"N/A") -> Anti-Skid Absorbent Insulation Coaster For Home Office | C29: =LARGE(IF('Cleaned Data'!$H$2:$H$112<>"",'Cleaned Data'!$H$2:$H$112),2) -> 5
A30: 3 | B30: =IFERROR(INDEX('Cleaned Data'!$A$2:$A$112,MATCH(LARGE(IF('Cleaned Data'!$H$2:$H$112<>"",'Cleaned Data'!$H$2:$H$112),3),'Cleaned Data'!$H$2:$H$112,0)),"N/A") -> Anti-Skid Absorbent Insulation Coaster For Home Office | C30: =LARGE(IF('Cleaned Data'!$H$2:$H$112<>"",'Cleaned Data'!$H$2:$H$112),3) -> 5
A31: 4 | B31: =IFERROR(INDEX('Cleaned Data'!$A$2:$A$112,MATCH(LARGE(IF('Cleaned Data'!$H$2:$H$112<>"",'Cleaned Data'!$H$2:$H$112),4),'Cleaned Data'!$H$2:$H$112,0)),"N/A") -> Anti-Skid Absorbent Insulation Coaster For Home Office | C31: =LARGE(IF('Cleaned Data'!$H$2:$H$112<>"",'Cleaned Data'!$H$2:$H$112),4) -> 5
A32: 5 | B32: =IFERROR(INDEX('Cleaned Data'!$A$2:$A$112,MATCH(LARGE(IF('Cleaned Data'!$H$2:$H$112<>"",'Cleaned Data'!$H$2:$H$112),5),'Cleaned Data'!$H$2:$H$112,0)),"N/A") -> Anti-Skid Absorbent Insulation Coaster For Home Office | C32: =LARGE(IF('Cleaned Data'!$H$2:$H$112<>"",'Cleaned Data'!$H$2:$H$112),5) -> 5
A34: TOP 5 LOWEST RATED PRODUCTS
A35: Rank | B35: Product | C35: Rating
A36: 1 | B36: =IFERROR(INDEX('Cleaned Data'!$A$2:$A$112,MATCH(SMALL(IF('Cleaned Data'!$H$2:$H$112<>"",'Cleaned Data'!$H$2:$H$112),1),'Cleaned Data'!$H$2:$H$112,0)),"N/A") -> Wall-mounted Sticker Punch-free Plug Fixer | C36: =IFERROR(SMALL(IF('Cleaned Data'!$H$2:$H$112<>"",'Cleaned Data'!$H$2:$H$112),1),"") -> 2
A37: 2 | B37: =IFERROR(INDEX('Cleaned Data'!$A$2:$A$112,MATCH(SMALL(IF('Cleaned Data'!$H$2:$H$112<>"",'Cleaned Data'!$H$2:$H$112),2),'Cleaned Data'!$H$2:$H$112,0)),"N/A") -> 5-PCS Stainless Steel Cooking Pot Set With Steamed Slices | C37: =IFERROR(SMALL(IF('Cleaned Data'!$H$2:$H$112<>"",'Cleaned Data'!$H$2:$H$112),2),"") -> 2.1
A38: 3 | B38: =IFERROR(INDEX('Cleaned Data'!$A$2:$A$112,MATCH(SMALL(IF('Cleaned Data'!$H$2:$H$112<>"",'Cleaned Data'!$H$2:$H$112),3),'Cleaned Data'!$H$2:$H$112,0)),"N/A") -> 5-PCS Stainless Steel Cooking Pot Set With Steamed Slices | C38: =IFERROR(SMALL(IF('Cleaned Data'!$H$2:$H$112<>"",'Cleaned Data'!$H$2:$H$112),3),"") -> 2.1
A39: 4 | B39: =IFERROR(INDEX('Cleaned Data'!$A$2:$A$112,MATCH(SMALL(IF('Cleaned Data'!$H$2:$H$112<>"",'Cleaned Data'!$H$2:$H$112),4),'Cleaned Data'!$H$2:$H$112,0)),"N/A") -> Artificial Potted Flowers Room Decorative Flowers (2 Pieces) | C39: =IFERROR(SMALL(IF('Cleaned Data'!$H$2:$H$112<>"",'Cleaned Data'!$H$2:$H$112),4),"") -> 2.2
A40: 5 | B40: =IFERROR(INDEX('Cleaned Data'!$A$2:$A$112,MATCH(SMALL(IF('Cleaned Data'!$H$2:$H$112<>"",'Cleaned Data'!$H$2:$H$112),5),'Cleaned Data'!$H$2:$H$112,0)),"N/A") -> Artificial Potted Flowers Room Decorative Flowers (2 Pieces) | C40: =IFERROR(SMALL(IF('Cleaned Data'!$H$2:$H$112<>"",'Cleaned Data'!$H$2:$H$112),5),"") -> 2.2
A42: TOP 10 PRODUCTS BY DISCOUNT %
A43: Rank | B43: Product | C43: Discount % | D43: Category
...

Sheet Pivot Data
A1: BY DISCOUNT CATEGORY
A2: Discount Category | B2: # Products | C2: Avg Price | D2: Avg Rating | E2: Avg Reviews
A3: High Discount | B3: =COUNTIF('Cleaned Data'!$F$2:$F$112,"High Discount") -> 62 | C3: =AVERAGEIF('Cleaned Data'!$F$2:$F$112,"High Discount",'Cleaned Data'!$B$2:$B$112) -> 756.41935 | D3: =AVERAGEIF('Cleaned Data'!$F$2:$F$112,"High Discount",'Cleaned Data'!$H$2:$H$112) -> 3.6133333 | E3: =AVERAGEIF('Cleaned Data'!$F$2:$F$112,"High Discount",'Cleaned Data'!$G$2:$G$112) -> 11.133333
A4: Medium Discount | B4: =COUNTIF('Cleaned Data'!$F$2:$F$112,"Medium Discount") -> 31 | C4: =AVERAGEIF('Cleaned Data'!$F$2:$F$112,"Medium Discount",'Cleaned Data'!$B$2:$B$112) -> 1579.6452 | D4: =AVERAGEIF('Cleaned Data'!$F$2:$F$112,"Medium Discount",'Cleaned Data'!$H$2:$H$112) -> 4.2681818 | E4: =AVERAGEIF('Cleaned Data'!$F$2:$F$112,"Medium Discount",'Cleaned Data'!$G$2:$G$112) -> 15.863636
A5: Low Discount | B5: =COUNTIF('Cleaned Data'!$F$2:$F$112,"Low Discount") -> 18 | C5: =AVERAGEIF('Cleaned Data'!$F$2:$F$112,"Low Discount",'Cleaned Data'!$B$2:$B$112) -> 1959.1667 | D5: =AVERAGEIF('Cleaned Data'!$F$2:$F$112,"Low Discount",'Cleaned Data'!$H$2:$H$112) -> 3.725 | E5: =AVERAGEIF('Cleaned Data'!$F$2:$F$112,"Low Discount",'Cleaned Data'!$G$2:$G$112) -> 9.5
A7: BY RATING CATEGORY
A8: Rating Category | B8: # Products | C8: Avg Price | D8: Avg Discount % | E8: Avg Reviews
A9: Excellent | B9: =COUNTIF('Cleaned Data'!$J$2:$J$112,"Excellent") -> 22 | C9: =AVERAGEIF('Cleaned Data'!$J$2:$J$112,"Excellent",'Cleaned Data'!$B$2:$B$112) -> 1381.0909 | D9: =AVERAGEIF('Cleaned Data'!$J$2:$J$112,"Excellent",'Cleaned Data'!$E$2:$E$112) -> 0.37499008 | E9: =AVERAGEIF('Cleaned Data'!$J$2:$J$112,"Excellent",'Cleaned Data'!$G$2:$G$112) -> 14.954545
A10: Average | B10: =COUNTIF('Cleaned Data'!$J$2:$J$112,"Average") -> 22 | C10: =AVERAGEIF('Cleaned Data'!$J$2:$J$112,"Average",'Cleaned Data'!$B$2:$B$112) -> 1369.4091 | D10: =AVERAGEIF('Cleaned Data'!$J$2:$J$112,"Average",'Cleaned Data'!$E$2:$E$112) -> 0.38033104 | E10: =AVERAGEIF('Cleaned Data'!$J$2:$J$112,"Average",'Cleaned Data'!$G$2:$G$112) -> 10.136364
A11: Poor | B11: =COUNTIF('Cleaned Data'!$J$2:$J$112,"Poor") -> 12 | C11: =AVERAGEIF('Cleaned Data'!$J$2:$J$112,"Poor",'Cleaned Data'!$B$2:$B$112) -> 998.33333 | D11: =AVERAGEIF('Cleaned Data'!$J$2:$J$112,"Poor",'Cleaned Data'!$E$2:$E$112) -> 0.43217789 | E11: =AVERAGEIF('Cleaned Data'!$J$2:$J$112,"Poor",'Cleaned Data'!$G$2:$G$112) -> 14.083333
A12: N/A | B12: =COUNTIF('Cleaned Data'!$J$2:$J$112,"N/A") -> 55 | C12: =AVERAGEIF('Cleaned Data'!$J$2:$J$112,"N/A",'Cleaned Data'!$B$2:$B$112) -> 1066.2 | D12: =AVERAGEIF('Cleaned Data'!$J$2:$J$112,"N/A",'Cleaned Data'!$E$2:$E$112) -> 0.34515064 | E12: =IFERROR(AVERAGEIF('Cleaned Data'!$J$2:$J$112,"N/A",'Cleaned Data'!$G$2:$G$112),"")
A14: DISCOUNT RANGE vs AVG REVIEWS (Trend Analysis)
A15: Discount Range | B15: # Products | C15: Avg Reviews | D15: Avg Rating
A16: <20% | B16: =COUNTIFS('Cleaned Data'!$E$2:$E$112,">=0",'Cleaned Data'!$E$2:$E$112,"<0.2") -> 18 | C16: =AVERAGEIFS('Cleaned Data'!$G$2:$G$112,'Cleaned Data'!$E$2:$E$112,">=0",'Cleaned Data'!$E$2:$E$112,"<0.2") -> 9.5 | D16: =AVERAGEIFS('Cleaned Data'!$H$2:$H$112,'Cleaned Data'!$E$2:$E$112,">=0",'Cleaned Data'!$E$2:$E$112,"<0.2") -> 3.725
A17: 20-30% | B17: =COUNTIFS('Cleaned Data'!$E$2:$E$112,">=0.2",'Cleaned Data'!$E$2:$E$112,"<0.3") -> 14 | C17: =AVERAGEIFS('Cleaned Data'!$G$2:$G$112,'Cleaned Data'!$E$2:$E$112,">=0.2",'Cleaned Data'!$E$2:$E$112,"<0.3") -> 18.545455 | D17: =AVERAGEIFS('Cleaned Data'!$H$2:$H$112,'Cleaned Data'!$E$2:$E$112,">=0.2",'Cleaned Data'!$E$2:$E$112,"<0.3") -> 4.2454545
A18: 30-40% | B18: =COUNTIFS('Cleaned Data'!$E$2:$E$112,">=0.3",'Cleaned Data'!$E$2:$E$112,"<0.4") -> 17 | C18: =AVERAGEIFS('Cleaned Data'!$G$2:$G$112,'Cleaned Data'!$E$2:$E$112,">=0.3",'Cleaned Data'!$E$2:$E$112,"<0.4") -> 13.181818 | D18: =AVERAGEIFS('Cleaned Data'!$H$2:$H$112,'Cleaned Data'!$E$2:$E$112,">=0.3",'Cleaned Data'!$E$2:$E$112,"<0.4") -> 4.2909091
A19: 40-50% | B19: =COUNTIFS('Cleaned Data'!$E$2:$E$112,">=0.4",'Cleaned Data'!$E$2:$E$112,"<0.5") -> 43 | C19: =AVERAGEIFS('Cleaned Data'!$G$2:$G$112,'Cleaned Data'!$E$2:$E$112,">=0.4",'Cleaned Data'!$E$2:$E$112,"<0.5") -> 13.157895 | D19: =AVERAGEIFS('Cleaned Data'!$H$2:$H$112,'Cleaned Data'!$E$2:$E$112,">=0.4",'Cleaned Data'!$E$2:$E$112,"<0.5") -> 3.6631579
A20: >50% | B20: =COUNTIFS('Cleaned Data'!$E$2:$E$112,">=0.5",'Cleaned Data'!$E$2:$E$112,"<1.0") -> 19 | C20: =AVERAGEIFS('Cleaned Data'!$G$2:$G$112,'Cleaned Data'!$E$2:$E$112,">=0.5",'Cleaned Data'!$E$2:$E$112,"<1.0") -> 7.6363636 | D20: =AVERAGEIFS('Cleaned Data'!$H$2:$H$112,'Cleaned Data'!$E$2:$E$112,">=0.5",'Cleaned Data'!$E$2:$E$112,"<1.0") -> 3.5272727

Sheet Discount Pivot
A3: Row Labels | B3: Sum of # Products | C3: Sum of Avg Rating | D3: Sum of Avg Reviews
A4: High Discount | B4: 62 | C4: 3.6133333 | D4: 11.133333
A5: Low Discount | B5: 18 | C5: 3.725 | D5: 9.5
A6: Medium Discount | B6: 31 | C6: 4.2681818 | D6: 15.863636
A7: Grand Total | B7: 111 | C7: 11.606515 | D7: 36.49697

Sheet Rating Pivot
A3: Categories | B3: Sum of Products | C3: Sum of Avg Price | D3: Avg Disc %
A4: Average | B4: 22 | C4: 1369.4091 | D4: 0.38033104
A5: Excellent | B5: 22 | C5: 1381.0909 | D5: 0.37499008
A6: N/A | B6: 55 | C6: 1066.2 | D6: 0.34515064
A7: Poor | B7: 12 | C7: 998.33333 | D7: 0.43217789
A8: Grand Total | B8: 111 | C8: 4815.0333 | D8: 1.5326497

Sheet Range Pivot
A2: DISCOUNT RANGE vs AVG REVIEWS (Trend Analysis)
A3: Row Labels | B3: Sum of # Products | C3: Sum of Avg Reviews | D3: Sum of Avg Rating
A4: <20% | B4: 18 | C4: 9.5 | D4: 3.725
A5: >50% | B5: 19 | C5: 7.6363636 | D5: 3.5272727
A6: 20-30% | B6: 14 | C6: 18.545455 | D6: 4.2454545
A7: 30-40% | B7: 17 | C7: 13.181818 | D7: 4.2909091
A8: 40-50% | B8: 43 | C8: 13.157895 | D8: 3.6631579
A9: Grand Total | B9: 111 | C9: 62.021531 | D9: 19.451794
